recipe_path: /home/ericdill/dev/conda-forge/feedstocks/feedstocks/conda-testenv/recipeTraceback (most recent call last):
  File "/home/ericdill/miniconda/lib/python3.6/site-packages/conda_build/build.py", line 1303, in test
    metadata_tuples = render_recipe(recipe_dir, config=config, reset_build_id=False)
  File "/home/ericdill/miniconda/lib/python3.6/site-packages/conda_build/render.py", line 539, in render_recipe
    m = MetaData(recipe_dir, config=config)
  File "/home/ericdill/miniconda/lib/python3.6/site-packages/conda_build/metadata.py", line 672, in __init__
    self.meta_path = find_recipe(path)
  File "/home/ericdill/miniconda/lib/python3.6/site-packages/conda_build/utils.py", line 785, in find_recipe
    raise IOError("More than one meta.yaml files found in %s" % path)
OSError: More than one meta.yaml files found in /tmp/tmp85z26dip

During handling of the above exception, another exception occurred:

Traceback (most recent call last):
  File "/home/ericdill/miniconda/lib/python3.6/site-packages/conda_build/build.py", line 1622, in build_tree
    test(pkg, config=metadata.config)
  File "/home/ericdill/miniconda/lib/python3.6/site-packages/conda_build/build.py", line 1310, in test
    raise IOError("Didn't find recipe in folder or package under test.  Can't test "
OSError: Didn't find recipe in folder or package under test.  Can't test this after exiting build.

During handling of the above exception, another exception occurred:

Traceback (most recent call last):
  File "/home/ericdill/miniconda/lib/python3.6/site-packages/conda_build/build.py", line 1487, in test
    utils.check_call_env(cmd, env=env, cwd=metadata.config.test_dir)
  File "/home/ericdill/miniconda/lib/python3.6/site-packages/conda_build/utils.py", line 670, in check_call_env
    return _func_defaulting_env_to_os_environ(subprocess.check_call, *popenargs, **kwargs)
  File "/home/ericdill/miniconda/lib/python3.6/site-packages/conda_build/utils.py", line 666, in _func_defaulting_env_to_os_environ
    return func(_args, **kwargs)
  File "/home/ericdill/miniconda/lib/python3.6/subprocess.py", line 291, in check_call
    raise CalledProcessError(retcode, cmd)
subprocess.CalledProcessError: Command '['/bin/bash', '-x', '-e', '/home/ericdill/miniconda/conda-bld/conda-testenv_1500238193284/test_tmp/conda_test_runner.sh']' returned non-zero exit status 1.

During handling of the above exception, another exception occurred:

Traceback (most recent call last):
  File "build-feedstocks.py", line 39, in build
    api.build(recipe_path)
  File "/home/ericdill/miniconda/lib/python3.6/site-packages/conda_build/api.py", line 183, in build
    need_source_download=need_source_download, config=config, variants=variants)
  File "/home/ericdill/miniconda/lib/python3.6/site-packages/conda_build/build.py", line 1633, in build_tree
    test(dict_and_meta[1], config=metadata.config)
  File "/home/ericdill/miniconda/lib/python3.6/site-packages/conda_build/build.py", line 1490, in test
    config=metadata.config)
  File "/home/ericdill/miniconda/lib/python3.6/site-packages/conda_build/build.py", line 1517, in tests_failed
    sys.exit("TESTS FAILED: " + os.path.basename(pkg))
SystemExit: TESTS FAILED: conda-testenv-0.1.0-py36h7980de7_1.tar.bz2
