recipe_path: /home/ericdill/dev/conda-forge/feedstocks/feedstocks/openssl/recipeTraceback (most recent call last):
  File "/home/ericdill/miniconda/lib/python3.6/site-packages/conda_build/environ.py", line 703, in get_install_actions
    actions = install_actions(prefix, index, specs, force=True)
  File "/home/ericdill/miniconda/lib/python3.6/site-packages/conda/plan.py", line 461, in install_actions
    update_deps, pinned)
  File "/home/ericdill/miniconda/lib/python3.6/site-packages/conda/plan.py", line 634, in get_actions_for_dists
    pkgs = r.install(specs, installed, update_deps=update_deps)
  File "/home/ericdill/miniconda/lib/python3.6/site-packages/conda/resolve.py", line 811, in install
    pkgs = self.solve(specs, returnall=returnall)
  File "/home/ericdill/miniconda/lib/python3.6/site-packages/conda/resolve.py", line 865, in solve
    self.find_conflicts(specs)
  File "/home/ericdill/miniconda/lib/python3.6/site-packages/conda/resolve.py", line 371, in find_conflicts
    raise UnsatisfiableError(bad_deps)
conda.exceptions.UnsatisfiableError: The following specifications were found to be in conflict:
  - perl 5.22.2.*
  - perl ==5.20.3.1
Use "conda info <package>" to see the dependencies for each package.

During handling of the above exception, another exception occurred:

Traceback (most recent call last):
  File "/home/ericdill/miniconda/lib/python3.6/site-packages/conda_build/environ.py", line 703, in get_install_actions
    actions = install_actions(prefix, index, specs, force=True)
  File "/home/ericdill/miniconda/lib/python3.6/site-packages/conda/plan.py", line 461, in install_actions
    update_deps, pinned)
  File "/home/ericdill/miniconda/lib/python3.6/site-packages/conda/plan.py", line 634, in get_actions_for_dists
    pkgs = r.install(specs, installed, update_deps=update_deps)
  File "/home/ericdill/miniconda/lib/python3.6/site-packages/conda/resolve.py", line 811, in install
    pkgs = self.solve(specs, returnall=returnall)
  File "/home/ericdill/miniconda/lib/python3.6/site-packages/conda/resolve.py", line 865, in solve
    self.find_conflicts(specs)
  File "/home/ericdill/miniconda/lib/python3.6/site-packages/conda/resolve.py", line 371, in find_conflicts
    raise UnsatisfiableError(bad_deps)
conda.exceptions.UnsatisfiableError: The following specifications were found to be in conflict:
  - perl 5.22.2.*
  - perl ==5.20.3.1
Use "conda info <package>" to see the dependencies for each package.

During handling of the above exception, another exception occurred:

Traceback (most recent call last):
  File "/home/ericdill/miniconda/lib/python3.6/site-packages/conda_build/environ.py", line 703, in get_install_actions
    actions = install_actions(prefix, index, specs, force=True)
  File "/home/ericdill/miniconda/lib/python3.6/site-packages/conda/plan.py", line 461, in install_actions
    update_deps, pinned)
  File "/home/ericdill/miniconda/lib/python3.6/site-packages/conda/plan.py", line 634, in get_actions_for_dists
    pkgs = r.install(specs, installed, update_deps=update_deps)
  File "/home/ericdill/miniconda/lib/python3.6/site-packages/conda/resolve.py", line 811, in install
    pkgs = self.solve(specs, returnall=returnall)
  File "/home/ericdill/miniconda/lib/python3.6/site-packages/conda/resolve.py", line 865, in solve
    self.find_conflicts(specs)
  File "/home/ericdill/miniconda/lib/python3.6/site-packages/conda/resolve.py", line 371, in find_conflicts
    raise UnsatisfiableError(bad_deps)
conda.exceptions.UnsatisfiableError: The following specifications were found to be in conflict:
  - perl 5.22.2.*
  - perl ==5.20.3.1
Use "conda info <package>" to see the dependencies for each package.

During handling of the above exception, another exception occurred:

Traceback (most recent call last):
  File "build-feedstocks.py", line 39, in build
    api.build(recipe_path)
  File "/home/ericdill/miniconda/lib/python3.6/site-packages/conda_build/api.py", line 183, in build
    need_source_download=need_source_download, config=config, variants=variants)
  File "/home/ericdill/miniconda/lib/python3.6/site-packages/conda_build/build.py", line 1615, in build_tree
    built_packages=built_packages,
  File "/home/ericdill/miniconda/lib/python3.6/site-packages/conda_build/build.py", line 999, in build
    output_metas = expand_outputs([(m, need_source_download, need_reparse_in_env)])
  File "/home/ericdill/miniconda/lib/python3.6/site-packages/conda_build/render.py", line 500, in expand_outputs
    for (output_dict, m) in _m.get_output_metadata_set(permit_unsatisfiable_variants=False):
  File "/home/ericdill/miniconda/lib/python3.6/site-packages/conda_build/metadata.py", line 1632, in get_output_metadata_set
    permit_unsatisfiable_variants=permit_unsatisfiable_variants)
  File "/home/ericdill/miniconda/lib/python3.6/site-packages/conda_build/metadata.py", line 622, in finalize_outputs_pass
    fm = finalize_metadata(om, permit_unsatisfiable_variants=permit_unsatisfiable_variants)
  File "/home/ericdill/miniconda/lib/python3.6/site-packages/conda_build/render.py", line 270, in finalize_metadata
    permit_unsatisfiable_variants=permit_unsatisfiable_variants)
  File "/home/ericdill/miniconda/lib/python3.6/site-packages/conda_build/render.py", line 112, in get_env_dependencies
    channel_urls=tuple(m.config.channel_urls))
  File "/home/ericdill/miniconda/lib/python3.6/site-packages/conda_build/environ.py", line 739, in get_install_actions
    channel_urls=tuple(channel_urls))
  File "/home/ericdill/miniconda/lib/python3.6/site-packages/conda_build/environ.py", line 739, in get_install_actions
    channel_urls=tuple(channel_urls))
  File "/home/ericdill/miniconda/lib/python3.6/site-packages/conda_build/environ.py", line 739, in get_install_actions
    channel_urls=tuple(channel_urls))
  File "/home/ericdill/miniconda/lib/python3.6/site-packages/conda_build/environ.py", line 703, in get_install_actions
    actions = install_actions(prefix, index, specs, force=True)
  File "/home/ericdill/miniconda/lib/python3.6/site-packages/conda/plan.py", line 461, in install_actions
    update_deps, pinned)
  File "/home/ericdill/miniconda/lib/python3.6/site-packages/conda/plan.py", line 634, in get_actions_for_dists
    pkgs = r.install(specs, installed, update_deps=update_deps)
  File "/home/ericdill/miniconda/lib/python3.6/site-packages/conda/resolve.py", line 811, in install
    pkgs = self.solve(specs, returnall=returnall)
  File "/home/ericdill/miniconda/lib/python3.6/site-packages/conda/resolve.py", line 865, in solve
    self.find_conflicts(specs)
  File "/home/ericdill/miniconda/lib/python3.6/site-packages/conda/resolve.py", line 371, in find_conflicts
    raise UnsatisfiableError(bad_deps)
conda.exceptions.UnsatisfiableError: The following specifications were found to be in conflict:
  - perl 5.22.2.*
  - perl ==5.20.3.1
Use "conda info <package>" to see the dependencies for each package.
